Workbook
Name \0: '[1]PNT-QUOT-#3'!#REF!
Name \0: '[1]PNT-QUOT-#3'!#REF!
Name \0: '[1]PNT-QUOT-#3'!#REF!
Name \a: #N/A
Name \c: #N/A
Name \C_1: #REF!
Name \d: #N/A
Name \dddddddd: #N/A
Name \ddddddddd: #N/A
Name \e: #N/A
Name \EXT: #REF!
Name \f: #REF!
Name \g: #REF!
Name \GUARD: #REF!
Name \i: #N/A
Name \j: #N/A
Name \k: #N/A
Name \KWS123: #N/A
Name \o: #REF!
Name \p: #REF!
Name \PUMP: #REF!
Name \q: #N/A
Name \s: #REF!
Name \t: #REF!
Name \u: #N/A
Name \z: '[1]COAT&WRAP-QIOT-#3'!#REF!
Name \z: '[1]COAT&WRAP-QIOT-#3'!#REF!
Name \z: '[1]COAT&WRAP-QIOT-#3'!#REF!
Name \ㅂ: #N/A
Name _: #N/A
Name _?1: #N/A
Name _?271: #N/A
Name __?1: #N/A
Name __?271: #N/A
Name ___??: #N/A
Name ___?1: #N/A
Name ___?271: #N/A
Name _____________________________________________a1: {"'Sheet1'!$L$16"}
Name _____________________________________________PA3: {"'Sheet1'!$L$16"}
Name ____________________________________________a1: {"'Sheet1'!$L$16"}
Name ____________________________________________PA3: {"'Sheet1'!$L$16"}
Name __________________________________________a1: {"'Sheet1'!$L$16"}
Name __________________________________________PA3: {"'Sheet1'!$L$16"}
Name _________________________________________a1: {"'Sheet1'!$L$16"}
Name _________________________________________PA3: {"'Sheet1'!$L$16"}
Name ________________________________________a1: {"'Sheet1'!$L$16"}
Name ________________________________________PA3: {"'Sheet1'!$L$16"}
Name _______________________________________a1: {"'Sheet1'!$L$16"}
Name _______________________________________PA3: {"'Sheet1'!$L$16"}
Name ______________________________________a1: {"'Sheet1'!$L$16"}
Name ______________________________________PA3: {"'Sheet1'!$L$16"}
Name _____________________________________a1: {"'Sheet1'!$L$16"}
Name _____________________________________PA3: {"'Sheet1'!$L$16"}
Name ____________________________________a1: {"'Sheet1'!$L$16"}
Name ____________________________________PA3: {"'Sheet1'!$L$16"}
Name ___________________________________PA3: {"'Sheet1'!$L$16"}
Name __________________________________a1: {"'Sheet1'!$L$16"}
Name __________________________________PA3: {"'Sheet1'!$L$16"}
Name _________________________________a1: {"'Sheet1'!$L$16"}
Name _________________________________PA3: {"'Sheet1'!$L$16"}

Sheet foxz

Sheet BIA
B10: BẢNG DỰ TOÁN CHI TIẾT
B12: 2/ HỆ THỐNG ĐIỆN TỔNG THỂ BÊN TRONG VÀ BÊN NGOÀI
B14: CÔNG TRÌNH: TRANG TRẠI CHĂN NUÔI LỢN CÔNG NGHỆ CAO TẠI XÃ QUẢNG SƠN, HUYỆN HẢI HÀ
B15: ĐỊA ĐIỂM: XÃ QUẢNG SƠN, HUYỆN HẢI HÀ, TỈNH QUẢNG NINH
B16: CHỦ ĐẦU TƯ: CÔNG TY CỔ PHẦN CHĂN NUÔI GREENTECH
B17: NHÀ THẦU ĐIỆN : CÔNG TY TNHH KỸ THUẬT ĐIỆN VÀ CÔNG NGHỆ MÔI TRƯỜNG DH
A26: QUANG NINH - 2023

Sheet P2-TONG HOP
A2: BẢNG TỔNG HỢP DỰ TOÁN CHI TIẾT
B3: =BIA!B14 -> CÔNG TRÌNH: TRANG TRẠI CHĂN NUÔI LỢN CÔNG NGHỆ CAO TẠI XÃ QUẢNG SƠN, HUYỆN HẢI HÀ
B4: =BIA!B15 -> ĐỊA ĐIỂM: XÃ QUẢNG SƠN, HUYỆN HẢI HÀ, TỈNH QUẢNG NINH
B5: =BIA!B16 -> CHỦ ĐẦU TƯ: CÔNG TY CỔ PHẦN CHĂN NUÔI GREENTECH
B6: NHÀ THẦU ĐIỆN : CÔNG TY TNHH KỸ THUẬT ĐIỆN VÀ CÔNG NGHỆ MÔI TRƯỜNG DH
A7: 2/ HỆ THỐNG ĐIỆN TỔNG THỂ BÊN TRONG VÀ BÊN NGOÀI
A8: STT | B8: Số hiệu hạng mục | C8: Hạng mục | D8: Đơn vị tính | E8: Số lượng | F8: Tổng Vật Tư | G8: Tổng Nhân Công | H8: Tổng khối lượng
A10: 01 | B10: I | C10: Cấp nguồn tổng thể | D10: Hệ thống | E10: 1 | F10: ='01.CẤP NGUỒN TỔNG THỂ'!J246 -> 4056691200 | G10: ='01.CẤP NGUỒN TỔNG THỂ'!K246 -> 1633788000 | H10: =+'01.CẤP NGUỒN TỔNG THỂ'!L246 -> 5690479200
A11: 02 | B11: II | C11: Hệ thống chiếu sáng ngoài | D11: Hệ thống | E11: 1 | F11: ='02.HỆ THỐNG CHIẾU SÁNG NGOÀI'!H86 -> 871221400 | G11: ='02.HỆ THỐNG CHIẾU SÁNG NGOÀI'!I86 -> 281816000 | H11: =+'02.HỆ THỐNG CHIẾU SÁNG NGOÀI'!J86 -> 1153037400
A12: 03 | B12: III | C12: Hệ thống tiếp địa | D12: Hệ thống | E12: 1 | F12: ='03.HỆ THỐNG TIẾP ĐỊA'!H182 -> 242599800 | G12: ='03.HỆ THỐNG TIẾP ĐỊA'!I182 -> 104537900 | H12: =+'03.HỆ THỐNG TIẾP ĐỊA'!J182 -> 347137700
A13: 04 | B13: IV | C13: Hệ thống chống sét | D13: Hệ thống | E13: 1 | F13: ='04.HỆ THỐNG CHỐNG SÉT'!H33 -> 410779200 | G13: ='04.HỆ THỐNG CHỐNG SÉT'!I33 -> 124599000 | H13: =+'04.HỆ THỐNG CHỐNG SÉT'!J33 -> 535378200
A14: 05 | B14: V | C14: Tủ điện | D14: Hệ thống | E14: 1 | F14: ='05.TỦ ĐIỆN'!H106 -> 3681003200 | G14: ='05.TỦ ĐIỆN'!I106 -> 344200000 | H14: =+'05.TỦ ĐIỆN'!J106 -> 4025203200
A15: 06 | B15: VI | C15: Hệ thống điện bên trong và ngoài | D15: Hệ thống | E15: 1 | F15: ='06.HỆ THỐNG CHIẾU SÁNG BÊN TRON'!H628 -> 5528387600 | G15: ='06.HỆ THỐNG CHIẾU SÁNG BÊN TRON'!I628 -> 2149611100 | H15: =+'06.HỆ THỐNG CHIẾU SÁNG BÊN TRON'!J628 -> 7677998800
A16: 07 | B16: VII | C16: Chi phí khác: chi phí quản lý, kho bãi, vệ sinh môi trường, an toàn lao động | D16: Hệ thống | E16: 1 | F16: 0 | G16: =SUM(F10:G15)*1% -> 194292344 | H16: =G16 -> 194292344
A17: TỔNG CỘNG I+II+III+IV+V+VI (trước VAT) | F17: =+SUM(F10:F16) -> 14790682400 | G17: =+SUM(G10:G16) -> 4832844344 | H17: =SUM(H10:H16) -> 19623526844
A18: THUẾ VAT 10%
A19: THUẾ VAT 8% | F19: =F17*0.08 -> 1183254592 | G19: =G17*8% -> 3.8662755e+08
A20: TỔNG CỘNG | F20: =SUM(F17:F19) -> 15973936992 | G20: =SUM(G17:G19) -> 5.2194719e+09 | H20: =SUM(F20:G20) -> 2.1193409e+10
A21: LÀM TRÒN SAU THUẾ | H21: 21193000000
A23: - Hiệu lực: Báo giá có hiệu lực trong vòng 3 tuần
A24: - Điều khoản thanh toán: Tạm ứng : 30%, Thanh toán lần 2, thanh toán lần 3 theo đợt tập kết vật tư
A25: - Tiến độ: Dự kiến 4-6 tháng, theo thỏa thuận và tiến độ thực tế công trường
A26: - Bảo hành: Theo tiêu chuẩn của hãng sản xuất 12 tháng
A27: CÔNG TY CỔ PHẦN CHĂN NUÔI GREENTECH | G27: CÔNG TY TNHH KỸ THUẬT ĐIỆN VÀ CÔNG NGHỆ MÔI TRƯỜNG DH

Sheet 01.CẤP NGUỒN TỔNG THỂ
A1: CHI TIẾT DỰ TOÁN
B2: =BIA!B14 -> CÔNG TRÌNH: TRANG TRẠI CHĂN NUÔI LỢN CÔNG NGHỆ CAO TẠI XÃ QUẢNG SƠN, HUYỆN HẢI HÀ
B3: =BIA!B15 -> ĐỊA ĐIỂM: XÃ QUẢNG SƠN, HUYỆN HẢI HÀ, TỈNH QUẢNG NINH
B4: =BIA!B16 -> CHỦ ĐẦU TƯ: CÔNG TY CỔ PHẦN CHĂN NUÔI GREENTECH
B5: NHÀ THẦU ĐIỆN : CÔNG TY TNHH KỸ THUẬT ĐIỆN VÀ CÔNG NGHỆ MÔI TRƯỜNG DH
B6: HẠNG MỤC P2-01: CẤP NGUỒN TỔNG THỂ
A7: STT | B7: NỘI DUNG CÔNG VIỆC | E7: XUẤT XỨ | F7: ĐVT | G7: Khối Lượng | H7: ĐƠN GIÁ | J7: Thành tiền | L7: Tổng Khối lượng | M7: GHI CHÚ
H8: Vật tư | I8: Nhân công | J8: Vật tư | K8: Nhân công
A9: I | B9: DÂY NGUỒN TỪ TRẠM BIẾN ÁP ĐẾN NHÀ MÁY PHÁT | J9: =SUM(J10:J44) -> 1375702000 | K9: =SUM(K10:K44) -> 89637000 | L9: =SUM(L10:L44) -> 1465339000
A10: 1 | B10: Cáp CXV 12x1C-240mm2 từ máy phát điện tới ngăn ATS của MSB | E10: Cadisun- Việt Nam | F10: m | G10: 0 | H10: 6572300 | I10: 390600 | J10: =ROUND(G10*H10,-3) -> 0 | K10: =ROUND(G10*I10,-3) -> 0 | L10: =J10+K10 -> 0
A11: 2 | B11: Cáp CXV 8x1C-185mm2 từ máy phát điện tới ngăn ATS của MSB-A.1 | C11: 185 | D11: 16 | E11: Cadisun- Việt Nam | F11: m | G11: 21 | H11: 3331200 | I11: 223200 | J11: =ROUND(G11*H11,-3) -> 69955000 | K11: =ROUND(G11*I11,-3) -> 4687000 | L11: =J11+K11 -> 74642000
A12: 3 | B12: Cáp CV 1C-120mm2 từ máy phát điện tới ngăn ATS của MSB-A.1 | C12: 120 | D12: 2 | E12: Cadisun- Việt Nam | F12: m | G12: 21 | H12: 266500 | I12: 21300 | J12: =ROUND(G12*H12,-3) -> 5597000 | K12: =ROUND(G12*I12,-3) -> 447000 | L12: =J12+K12 -> 6044000 | M12: Bổ sung dây tiếp địa
A13: 4 | B13: Cáp CXV 8x1C-185mm2 từ máy phát điện tới ngăn ATS của MSB-A.2 | C13: 185 | D13: 16 | E13: Cadisun- Việt Nam | F13: m | G13: 27 | H13: 3331200 | I13: 223200 | J13: =ROUND(G13*H13,-3) -> 89942000 | K13: =ROUND(G13*I13,-3) -> 6026000 | L13: =J13+K13 -> 95968000
A14: 5 | B14: Cáp CV 1C-120mm2 từ máy phát điện tới ngăn ATS của MSB-A.2 | C14: 120 | D14: 2 | E14: Cadisun- Việt Nam | F14: m | G14: 27 | H14: 266500 | I14: 21300 | J14: =ROUND(G14*H14,-3) -> 7196000 | K14: =ROUND(G14*I14,-3) -> 575000 | L14: =J14+K14 -> 7771000 | M14: Bổ sung dây tiếp địa
A15: 6 | B15: Cáp CXV 2x1C-300mm2 từ máy phát điện tới ngăn ATS của MSB | E15: Cadisun- Việt Nam | F15: m | G15: 0 | H15: 0 | I15: 0 | J15: =ROUND(G15*H15,-3) -> 0 | K15: =ROUND(G15*I15,-3) -> 0 | L15: =J15+K15 -> 0
A16: 7 | B16: Cáp CXV 11x1C-300mm² từ máy phát điện tới ngăn ATS của MSB-B.1 | C16: 300 | D16: 22 | E16: Cadisun- Việt Nam | F16: m | G16: 22 | H16: 7528400 | I16: 409200 | J16: =ROUND(G16*H16,-3) -> 165625000 | K16: =ROUND(G16*I16,-3) -> 9002000 | L16: =J16+K16 -> 174627000
A17: 8 | B17: Cáp CV 1C-120mm2 từ máy phát điện tới ngăn ATS của MSB-B.1 | C17: 120 | D17: 2 | E17: Cadisun- Việt Nam | F17: m | G17: 22 | H17: 266500 | I17: 21300 | J17: =ROUND(G17*H17,-3) -> 5863000 | K17: =ROUND(G17*I17,-3) -> 469000 | L17: =J17+K17 -> 6332000 | M17: Bổ sung dây tiếp địa
A18: 9 | B18: Cáp CXV 11x1C-300mm² từ máy phát điện tới ngăn ATS của MSB-B.2 | C18: 300 | D18: 22 | E18: Cadisun- Việt Nam | F18: m | G18: 28 | H18: 7528400 | I18: 409200 | J18: =ROUND(G18*H18,-3) -> 210795000 | K18: =ROUND(G18*I18,-3) -> 11458000 | L18: =J18+K18 -> 222253000
A19: 10 | B19: Cáp CV 1C-120mm2 từ máy phát điện tới ngăn ATS của MSB-B.2 | C19: 120 | D19: 2 | E19: Cadisun- Việt Nam | F19: m | G19: 28 | H19: 266500 | I19: 21300 | J19: =ROUND(G19*H19,-3) -> 7462000 | K19: =ROUND(G19*I19,-3) -> 596000 | L19: =J19+K19 -> 8058000 | M19: Bổ sung dây tiếp địa
A20: 11 | B20: Cáp CXV 12x1C-300mm2 từ trạm biến áp tới ngăn ATS của MSB | E20: Cadisun- Việt Nam | F20: m | G20: 0 | H20: 8212800 | I20: 446400 | J20: =ROUND(G20*H20,-3) -> 0 | K20: =ROUND(G20*I20,-3) -> 0 | L20: =J20+K20 -> 0
A21: 12 | B21: Cáp CXV 11x1C-300mm2 từ trạm biến áp tới ngăn ATS của MSB-A | C21: 300 | D21: 22 | E21: Cadisun- Việt Nam | F21: m | G21: 19 | H21: 7528400 | I21: 409200 | J21: =ROUND(G21*H21,-3) -> 143040000 | K21: =ROUND(G21*I21,-3) -> 7775000 | L21: =J21+K21 -> 150815000
A22: 13 | B22: Cáp CV 1C-120mm2 từ máy phát điện tới ngăn ATS của MSB-A.1 | C22: 120 | D22: 2 | E22: Cadisun- Việt Nam | F22: m | G22: 19 | H22: 266500 | I22: 21300 | J22: =ROUND(G22*H22,-3) -> 5064000 | K22: =ROUND(G22*I22,-3) -> 405000 | L22: =J22+K22 -> 5469000 | M22: Bổ sung dây tiếp địa
A23: 14 | B23: Cáp CXV 8x1C-185mm2 từ MSB-A tới MSB-A.1 | C23: 185 | D23: 16 | E23: Cadisun- Việt Nam | F23: m | G23: 14 | H23: 3331200 | I23: 223200 | J23: =ROUND(G23*H23,-3) -> 46637000 | K23: =ROUND(G23*I23,-3) -> 3125000 | L23: =J23+K23 -> 49762000
A24: 15 | B24: Cáp CV 1C-120mm2 từ máy phát điện tới ngăn ATS của MSB-A.1 | C24: 120 | D24: 2 | E24: Cadisun- Việt Nam | F24: m | G24: 14 | H24: 266500 | I24: 21300 | J24: =ROUND(G24*H24,-3) -> 3731000 | K24: =ROUND(G24*I24,-3) -> 298000 | L24: =J24+K24 -> 4029000 | M24: Bổ sung dây tiếp địa
A25: 16 | B25: Cáp CXV 8x1C-185mm2 từ MSB-A tới MSB-A.2 | C25: 185 | D25: 16 | E25: Cadisun- Việt Nam | F25: m | G25: 16 | H25: 3331200 | I25: 223200 | J25: =ROUND(G25*H25,-3) -> 53299000 | K25: =ROUND(G25*I25,-3) -> 3571000 | L25: =J25+K25 -> 56870000
A26: 17 | B26: Cáp CV 1C-120mm2 từ máy phát điện tới ngăn ATS của MSB-A.2 | C26: 120 | D26: 2 | E26: Cadisun- Việt Nam | F26: m | G26: 16 | H26: 266500 | I26: 21300 | J26: =ROUND(G26*H26,-3) -> 4264000 | K26: =ROUND(G26*I26,-3) -> 341000 | L26: =J26+K26 -> 4605000 | M26: Bổ sung dây tiếp địa
A27: 18 | B27: Cáp CXV 4C-10mm2 | E27: Cadisun- Việt Nam | F27: m | G27: 0 | H27: 185000 | I27: 23200 | J27: =ROUND(G27*H27,-3) -> 0 | K27: =ROUND(G27*I27,-3) -> 0 | L27: =J27+K27 -> 0
A28: 19 | B28: Cáp CXV 15x1C-300mm2 từ trạm biến áp tới ngăn ATS của MSB-B | E28: Cadisun- Việt Nam | F28: m | G28: 0 | H28: 10266000 | I28: 558000 | J28: =ROUND(G28*H28,-3) -> 0 | K28: =ROUND(G28*I28,-3) -> 0 | L28: =J28+K28 -> 0
A29: 20 | B29: Cáp CXV 18x1C-300mm2 từ trạm biến áp tới ngăn ATS của MSB-B | C29: 300 | D29: 36 | E29: Cadisun- Việt Nam | F29: m | G29: 19 | H29: 12319200 | I29: 669600 | J29: =ROUND(G29*H29,-3) -> 234065000 | K29: =ROUND(G29*I29,-3) -> 12722000 | L29: =J29+K29 -> 246787000
A30: 21 | B30: Cáp CV 1C-120mm2 từ máy phát điện tới ngăn ATS của MSB-B | C30: 120 | D30: 2 | E30: Cadisun- Việt Nam | F30: m | G30: 19 | H30: 266500 | I30: 21300 | J30: =ROUND(G30*H30,-3) -> 5064000 | K30: =ROUND(G30*I30,-3) -> 405000 | L30: =J30+K30 -> 5469000 | M30: Bổ sung dây tiếp địa
A31: 22 | B31: Cáp CXV 11x1C-300mm2 từ MSB-B tới MSB-B.1 | C31: 300 | D31: 22 | E31: Cadisun- Việt Nam | F31: m | G31: 14 | H31: 7528400 | I31: 409200 | J31: =ROUND(G31*H31,-3) -> 105398000 | K31: =ROUND(G31*I31,-3) -> 5729000 | L31: =J31+K31 -> 111127000
A32: 23 | B32: Cáp CV 1C-120mm2 từ máy phát điện tới ngăn ATS của MSB-B.1 | C32: 120 | D32: 2 | E32: Cadisun- Việt Nam | F32: m | G32: 14 | H32: 266500 | I32: 21300 | J32: =ROUND(G32*H32,-3) -> 3731000 | K32: =ROUND(G32*I32,-3) -> 298000 | L32: =J32+K32 -> 4029000 | M32: Bổ sung dây tiếp địa
A33: 24 | B33: Cáp CXV 11x1C-300mm2 từ MSB-B tới MSB-B.2 | C33: 300 | D33: 22 | E33: Cadisun- Việt Nam | F33: m | G33: 16 | H33: 7528400 | I33: 409200 | J33: =ROUND(G33*H33,-3) -> 120454000 | K33: =ROUND(G33*I33,-3) -> 6547000 | L33: =J33+K33 -> 127001000
A34: 25 | B34: Cáp CV 1C-120mm2 từ máy phát điện tới ngăn ATS của MSB-B.2 | C34: 120 | D34: 2 | E34: Cadisun- Việt Nam | F34: m | G34: 16 | H34: 266500 | I34: 21300 | J34: =ROUND(G34*H34,-3) -> 4264000 | K34: =ROUND(G34*I34,-3) -> 341000 | L34: =J34+K34 -> 4605000 | M34: Bổ sung dây tiếp địa
A35: 26 | B35: Cáp CVV 2C_6mm2 | E35: Cadisun- Việt Nam | F35: m | G35: 0 | H35: 31300 | I35: 9300 | J35: =ROUND(G35*H35,-3) -> 0 | K35: =ROUND(G35*I35,-3) -> 0 | L35: =J35+K35 -> 0
A36: 27 | B36: Cáp CXV 2x1C-300mm2 từ trạm biến áp tới ngăn ATS của MSB | E36: Cadisun- Việt Nam | F36: m | G36: 0 | H36: 1368700 | I36: 74400 | J36: =ROUND(G36*H36,-3) -> 0 | K36: =ROUND(G36*I36,-3) -> 0 | L36: =J36+K36 -> 0
A37: 28 | B37: Cáp CXV 4C_50mm2 | E37: Cadisun- Việt Nam | F37: m | G37: 0 | H37: 444200 | I37: 79000 | J37: =ROUND(G37*H37,-3) -> 0 | K37: =ROUND(G37*I37,-3) -> 0 | L37: =J37+K37 -> 0
A38: 29 | B38: Ống xoẳn ruột gà HDPE D195/170mm | E38: TC- Việt Nam | F38: m | G38: 75 | H38: 96800 | I38: 26900 | J38: =ROUND(G38*H38,-3) -> 7260000 | K38: =ROUND(G38*I38,-3) -> 2018000 | L38: =J38+K38 -> 9278000
A39: 30 | B39: Đào và lấp đất bao gồm cát, gạch, … | E39: Việt Nam | F39: m3 | G39: 16 | H39: 0 | I39: 139500 | J39: =ROUND(G39*H39,-3) -> 0 | K39: =ROUND(G39*I39,-3) -> 2232000 | L39: =J39+K39 -> 2232000
A40: 31 | B40: Thang cáp 500x200x1.5mm ( không nắp ) | E40: VN | F40: m | G40: 75 | H40: 310600 | I40: 79000 | J40: =ROUND(G40*H40,-3) -> 23295000 | K40: =ROUND(G40*I40,-3) -> 5925000 | L40: =J40+K40 -> 29220000
...

Sheet 02.HỆ THỐNG CHIẾU SÁNG NGOÀI
A1: CHI TIẾT DỰ TOÁN
B2: =BIA!B14 -> CÔNG TRÌNH: TRANG TRẠI CHĂN NUÔI LỢN CÔNG NGHỆ CAO TẠI XÃ QUẢNG SƠN, HUYỆN HẢI HÀ
B3: =BIA!B15 -> ĐỊA ĐIỂM: XÃ QUẢNG SƠN, HUYỆN HẢI HÀ, TỈNH QUẢNG NINH
B4: =BIA!B16 -> CHỦ ĐẦU TƯ: CÔNG TY CỔ PHẦN CHĂN NUÔI GREENTECH
B5: NHÀ THẦU ĐIỆN : CÔNG TY TNHH KỸ THUẬT ĐIỆN VÀ CÔNG NGHỆ MÔI TRƯỜNG DH
B6: HẠNG MỤC P2-02: HỆ THỐNG CHIẾU SÁNG NGOÀI
A7: STT | B7: NỘI DUNG CÔNG VIỆC | C7: XUẤT XỨ | D7: ĐVT | E7: Khối Lượng | F7: ĐƠN GIÁ | H7: Thành tiền | J7: Tổng Khối lượng | K7: GHI CHÚ
F8: Vật tư | G8: Nhân công | H8: Vật tư | I8: Nhân công
A9: A | B9: CHIẾU SÁNG KHU VỰC NGOẠI KHU CHUỒNG TRẠI | H9: =SUM(H10:H16) -> 434358500 | I9: =SUM(I10:I16) -> 74539500 | J9: =SUM(J10:J16) -> 508898000
A10: 1 | B10: Đèn pha led 100W công nghiệp IP65 kèm bộ sạc NLMT gắn trụ | C10: Duhal- Việt Nam | D10: bộ | E10: 4 | F10: 2926000 | G10: 232500 | H10: =E10*F10 -> 11704000 | I10: =E10*G10 -> 930000 | J10: =SUM(H10,I10) -> 12634000
A11: =A10+1 -> 2 | B11: Đèn pha led 100W công nghiệp IP65 kèm bộ sạc NLMT gắn vách | C11: Duhal- Việt Nam | D11: bộ | E11: 75 | F11: 2926000 | G11: 232500 | H11: =E11*F11 -> 219450000 | I11: =E11*G11 -> 17437500 | J11: =SUM(H11,I11) -> 236887500
A12: =A11+1 -> 3 | B12: Móng trụ đèn 800x800 | C12: Vn | D12: Cái | E12: 4 | F12: 1584100 | G12: 465000 | H12: =E12*F12 -> 6336400 | I12: =E12*G12 -> 1860000 | J12: =SUM(H12,I12) -> 8196400
A13: =A12+1 -> 4 | B13: Trụ đèn tròn côn cao 6m | C13: Vn | D13: Cây | E13: 4 | F13: 2731200 | G13: 604500 | H13: =E13*F13 -> 10924800 | I13: =E13*G13 -> 2418000 | J13: =SUM(H13,I13) -> 13342800
A14: =A13+1 -> 5 | B14: Cần đèn sắt tráng kẽm phi 60 cao 2 mét | C14: Vn | D14: Cây | E14: 4 | F14: 928600 | G14: 139500 | H14: =E14*F14 -> 3714400 | I14: =E14*G14 -> 558000 | J14: =SUM(H14,I14) -> 4272400
A15: =A14+1 -> 6 | B15: Vật tư phụ: Đầu cos, dây rút và vật tư tiêu hao hoàn thiện công việc | D15: Lô | E15: 11 | F15: 16387500 | G15: 4650000 | H15: =E15*F15 -> 180262500 | I15: =E15*G15 -> 51150000 | J15: =SUM(H15,I15) -> 231412500
A16: =A15+1 -> 7 | B16: Tiếp địa | D16: Hệ | E16: 4 | F16: 491600 | G16: 46500 | H16: =E16*F16 -> 1966400 | I16: =E16*G16 -> 186000 | J16: =SUM(H16,I16) -> 2152400
A17: B | B17: CHIẾU SÁNG SÂN BÓNG (2 SÂN) | F17: 0 | G17: 0 | H17: =SUM(H18:H32) -> 107584200 | I17: =SUM(I18:I32) -> 35137400 | J17: =SUM(J18:J32) -> 142721600
A18: 1 | B18: Đèn pha led 100W công nghiệp IP65 | C18: Duhal- Việt Nam | D18: bộ | E18: 12 | F18: 885200 | G18: 232500 | H18: =E18*F18 -> 10622400 | I18: =E18*G18 -> 2790000 | J18: =SUM(H18,I18) -> 13412400
A19: =A18+1 -> 2 | B19: Cáp CXV 3x(1C-2.5mm2) từ MCB tới công tắc | C19: Cadisun- Việt Nam | D19: m | E19: 30 | F19: 18500 | G19: 5500 | H19: =E19*F19 -> 555000 | I19: =E19*G19 -> 165000 | J19: =SUM(H19,I19) -> 720000
A20: =A19+1 -> 3 | B20: Cáp CXV 3x(1C-2.5mm2) từ công tắc đến chân cột | C20: Cadisun- Việt Nam | D20: m | E20: 240 | F20: 18500 | G20: 5500 | H20: =E20*F20 -> 4440000 | I20: =E20*G20 -> 1320000 | J20: =SUM(H20,I20) -> 5760000
A21: =A20+1 -> 4 | B21: Cáp CXV 3x(1C-1.5mm2) từ chân cột tới đèn | C21: Cadisun- Việt Nam | D21: m | E21: 96 | F21: 11100 | G21: 1300 | H21: =E21*F21 -> 1065600 | I21: =E21*G21 -> 124800 | J21: =SUM(H21,I21) -> 1190400
A22: =A21+1 -> 5 | B22: Công tắc đơn 1 chiều 20A | C22: Sino- Việt Nam | D22: bộ | E22: 2 | F22: 27000 | G22: 13900 | H22: =E22*F22 -> 54000 | I22: =E22*G22 -> 27800 | J22: =SUM(H22,I22) -> 81800
A23: =A22+1 -> 6 | B23: Ống xoắn ruột gà HDPE D40/30 | C23: Sino- Việt Nam | D23: m | E23: 240 | F23: 8300 | G23: 9300 | H23: =E23*F23 -> 1992000 | I23: =E23*G23 -> 2232000 | J23: =SUM(H23,I23) -> 4224000
A24: =A23+1 -> 7 | B24: Đào và lắp đất | C24: Việt Nam | D24: m3 | E24: 58 | F24: 0 | G24: 139500 | H24: =E24*F24 -> 0 | I24: =E24*G24 -> 8091000 | J24: =SUM(H24,I24) -> 8091000
A25: =A24+1 -> 8 | B25: Móng trụ đèn 800x800 | C25: VN | D25: cái | E25: 12 | F25: 1802600 | G25: 186000 | H25: =E25*F25 -> 21631200 | I25: =E25*G25 -> 2232000 | J25: =SUM(H25,I25) -> 23863200
A26: =A25+1 -> 9 | B26: Trụ đèn tròn côn cao 6m | C26: VN | D26: cây | E26: 12 | F26: 2731200 | G26: 465000 | H26: =E26*F26 -> 32774400 | I26: =E26*G26 -> 5580000 | J26: =SUM(H26,I26) -> 38354400
A27: =A26+1 -> 10 | B27: Cần đèn sắt tráng kẽm phi 60 cao 2 mét | C27: VN | D27: bộ | E27: 12 | F27: 928600 | G27: 139500 | H27: =E27*F27 -> 11143200 | I27: =E27*G27 -> 1674000 | J27: =SUM(H27,I27) -> 12817200
A28: =A27+1 -> 11 | B28: Cáp đồng trần 10mm2 | C28: Vn | D28: Mét | E28: 132 | F28: 23800 | G28: 7900 | H28: =E28*F28 -> 3141600 | I28: =E28*G28 -> 1042800 | J28: =SUM(H28,I28) -> 4184400
A29: =A28+1 -> 12 | B29: Cọc tiếp địa L=2.4m, D16 | C29: Vn | D29: Cọc | E29: 36 | F29: 218500 | G29: 46500 | H29: =E29*F29 -> 7866000 | I29: =E29*G29 -> 1674000 | J29: =SUM(H29,I29) -> 9540000
A30: =A29+1 -> 13 | B30: Hàn hóa nhiệt | C30: VN | D30: Mối | E30: 36 | F30: 163800 | G30: 186000 | H30: =E30*F30 -> 5896800 | I30: =E30*G30 -> 6696000 | J30: =SUM(H30,I30) -> 12592800
A31: =A30+1 -> 14 | B31: Hóa chất giảm điện trở | C31: VN | D31: bao | E31: 12 | F31: 305900 | G31: 46500 | H31: =E31*F31 -> 3670800 | I31: =E31*G31 -> 558000 | J31: =SUM(H31,I31) -> 4228800
A32: =A31+1 -> 15 | B32: Vật tư phụ: Đầu cos, dây rút và vật tư tiêu hao hoàn thiện công việc | D32: Lô | E32: 1 | F32: 2731200 | G32: 930000 | H32: =E32*F32 -> 2731200 | I32: =E32*G32 -> 930000 | J32: =SUM(H32,I32) -> 3661200
A33: C | B33: CHIẾU SÁNG NỘI KHU CHUỒNG TRẠI | F33: 0 | G33: 0 | H33: =SUM(H35:H63) -> 210275200 | I33: =SUM(I35:I63) -> 99663500 | J33: =SUM(J35:J63) -> 309938700
A34: I | B34: CHUỒNG HEO THỊT | F34: 0 | G34: 0
A35: 1 | B35: Đèn pha led 100W công nghiệp IP65 | C35: Duhal- Việt Nam | D35: bộ | E35: 32 | F35: 885200 | G35: 232500 | H35: =E35*F35 -> 28326400 | I35: =E35*G35 -> 7440000 | J35: =SUM(H35,I35) -> 35766400
A36: =A35+1 -> 2 | B36: Cáp Cu/PVC/PVC 3x(1C-2.5mm2) từ MCB tới đèn | C36: Cadisun- Việt Nam | D36: m | E36: 3150 | F36: 18500 | G36: 5500 | H36: =E36*F36 -> 58275000 | I36: =E36*G36 -> 17325000 | J36: =SUM(H36,I36) -> 75600000
A37: =A36+1 -> 3 | B37: Ống điện PVC D20 | C37: Sino- Việt Nam | D37: m | E37: 2900 | F37: 6800 | G37: 9300 | H37: =E37*F37 -> 19720000 | I37: =E37*G37 -> 26970000 | J37: =SUM(H37,I37) -> 46690000 | K37: Giảm số m ống
A38: =A37+1 -> 4 | B38: Vật tư phụ: Đầu cos, dây rút và vật tư tiêu hao hoàn thiện công việc | D38: Lô | E38: 1 | F38: 3348700 | G38: 465000 | H38: =E38*F38 -> 3348700 | I38: =E38*G38 -> 465000 | J38: =SUM(H38,I38) -> 3813700
A39: II | B39: CHUỒNG HEO CAI SỮA | F39: 0 | G39: 0
A40: 1 | B40: Đèn pha led 100W công nghiệp IP65 | C40: Duhal- Việt Nam | D40: bộ | E40: 6 | F40: 885200 | G40: 232500 | H40: =E40*F40 -> 5311200 | I40: =E40*G40 -> 1395000 | J40: =SUM(H40,I40) -> 6706200
...

Sheet 03.HỆ THỐNG TIẾP ĐỊA
A1: CHI TIẾT DỰ TOÁN
B2: =BIA!B14 -> CÔNG TRÌNH: TRANG TRẠI CHĂN NUÔI LỢN CÔNG NGHỆ CAO TẠI XÃ QUẢNG SƠN, HUYỆN HẢI HÀ
B3: =BIA!B15 -> ĐỊA ĐIỂM: XÃ QUẢNG SƠN, HUYỆN HẢI HÀ, TỈNH QUẢNG NINH
B4: =BIA!B16 -> CHỦ ĐẦU TƯ: CÔNG TY CỔ PHẦN CHĂN NUÔI GREENTECH
B5: NHÀ THẦU ĐIỆN : CÔNG TY TNHH KỸ THUẬT ĐIỆN VÀ CÔNG NGHỆ MÔI TRƯỜNG DH
B6: HẠNG MỤC P2-03: HỆ THỐNG TIẾP ĐỊA
A7: STT | B7: NỘI DUNG CÔNG VIỆC | C7: XUẤT XỨ | D7: ĐVT | E7: Khối Lượng | F7: ĐƠN GIÁ | H7: Thành tiền | J7: Tổng Khối lượng | K7: GHI CHÚ
F8: Vật tư | G8: Nhân công | H8: Vật tư | I8: Nhân công
A10: I | B10: HỆ THỐNG TIẾP ĐỊA TỦ ĐIỆN MSB-A | H10: =SUM(H11:H18) -> 9256900 | I10: =SUM(I11:I18) -> 2501700 | J10: =SUM(J11:J18) -> 11758600
A11: 1 | B11: Cáp đồng trần 70mm2 | C11: Cadisun- Việt Nam | D11: Mét | E11: 31 | F11: 154800 | G11: 19500 | H11: =E11*F11 -> 4798800 | I11: =E11*G11 -> 604500 | J11: =SUM(H11,I11) -> 5403300
A12: 2 | B12: Ống xoắn ruột gà HDPE D40/30 | C12: TC- Việt Nam | D12: Mét | E12: 12 | F12: 8300 | G12: 9300 | H12: =E12*F12 -> 99600 | I12: =E12*G12 -> 111600 | J12: =SUM(H12,I12) -> 211200
A13: 3 | B13: Cọc tiếp địa L=2.4m, D16 | C13: Ấn độ | D13: Cọc | E13: 6 | F13: 218500 | G13: 46500 | H13: =E13*F13 -> 1311000 | I13: =E13*G13 -> 279000 | J13: =SUM(H13,I13) -> 1590000
A14: 4 | B14: Hộp kiểm tra điện trở | C14: VN | D14: Cái | E14: 1 | F14: 491600 | G14: 139500 | H14: =E14*F14 -> 491600 | I14: =E14*G14 -> 139500 | J14: =SUM(H14,I14) -> 631100
A15: 5 | B15: Hàn hóa nhiệt | C15: VN | D15: Mối | E15: 6 | F15: 163800 | G15: 186000 | H15: =E15*F15 -> 982800 | I15: =E15*G15 -> 1116000 | J15: =SUM(H15,I15) -> 2098800
A16: 6 | B16: Thanh tiếp địa bằng đồng 350x50x5mm | D16: thanh | E16: 1 | F16: 109200 | G16: 18600 | H16: =E16*F16 -> 109200 | I16: =E16*G16 -> 18600 | J16: =SUM(H16,I16) -> 127800
A17: 7 | B17: Hóa chất giảm điện trở | D17: bao | E17: 3 | F17: 305900 | G17: 46500 | H17: =E17*F17 -> 917700 | I17: =E17*G17 -> 139500 | J17: =SUM(H17,I17) -> 1057200
A18: =A17+1 -> 8 | B18: Vật tư phụ | D18: lô | E18: 1 | F18: 546200 | G18: 93000 | H18: =E18*F18 -> 546200 | I18: =E18*G18 -> 93000 | J18: =SUM(H18,I18) -> 639200
A19: II | B19: HỆ THỐNG TIẾP ĐỊA TỦ ĐIỆN MSB-B | F19: 0 | G19: 0 | H19: =SUM(H20:H27) -> 9256900 | I19: =SUM(I20:I27) -> 2501700 | J19: =SUM(J20:J27) -> 11758600
A20: 1 | B20: Cáp đồng trần 70mm2 | C20: Cadisun- Việt Nam | D20: Mét | E20: 31 | F20: 154800 | G20: 19500 | H20: =E20*F20 -> 4798800 | I20: =E20*G20 -> 604500 | J20: =SUM(H20,I20) -> 5403300
A21: 2 | B21: Ống xoắn ruột gà HDPE D40/30 | C21: TC- Việt Nam | D21: Mét | E21: 12 | F21: 8300 | G21: 9300 | H21: =E21*F21 -> 99600 | I21: =E21*G21 -> 111600 | J21: =SUM(H21,I21) -> 211200
A22: 3 | B22: Cọc tiếp địa L=2.4m, D16 | C22: Ấn độ | D22: Cọc | E22: 6 | F22: 218500 | G22: 46500 | H22: =E22*F22 -> 1311000 | I22: =E22*G22 -> 279000 | J22: =SUM(H22,I22) -> 1590000
A23: 4 | B23: Hộp kiểm tra điện trở | C23: VN | D23: Cái | E23: 1 | F23: 491600 | G23: 139500 | H23: =E23*F23 -> 491600 | I23: =E23*G23 -> 139500 | J23: =SUM(H23,I23) -> 631100
A24: 5 | B24: Hàn hóa nhiệt | C24: VN | D24: Mối | E24: 6 | F24: 163800 | G24: 186000 | H24: =E24*F24 -> 982800 | I24: =E24*G24 -> 1116000 | J24: =SUM(H24,I24) -> 2098800
A25: 6 | B25: Thanh tiếp địa bằng đồng 350x50x5mm | D25: thanh | E25: 1 | F25: 109200 | G25: 18600 | H25: =E25*F25 -> 109200 | I25: =E25*G25 -> 18600 | J25: =SUM(H25,I25) -> 127800
A26: 7 | B26: Hóa chất giảm điện trở | D26: bao | E26: 3 | F26: 305900 | G26: 46500 | H26: =E26*F26 -> 917700 | I26: =E26*G26 -> 139500 | J26: =SUM(H26,I26) -> 1057200
A27: =A26+1 -> 8 | B27: Vật tư phụ | D27: lô | E27: 1 | F27: 546200 | G27: 93000 | H27: =E27*F27 -> 546200 | I27: =E27*G27 -> 93000 | J27: =SUM(H27,I27) -> 639200
A28: III | B28: HỆ THỐNG TIẾP ĐỊA TỦ ĐIỆN MDB-2A | F28: 0 | G28: 0 | H28: =SUM(H29:H35) -> 9147700 | I28: =SUM(I29:I35) -> 2483100 | J28: =SUM(J29:J35) -> 11630800
A29: 1 | B29: Cáp đồng trần 70mm2 | C29: Cadisun- Việt Nam | D29: Mét | E29: 31 | F29: 154800 | G29: 19500 | H29: =E29*F29 -> 4798800 | I29: =E29*G29 -> 604500 | J29: =SUM(H29,I29) -> 5403300
A30: 2 | B30: Ống xoắn ruột gà HDPE D50/40 | C30: TC- Việt Nam | D30: Mét | E30: 12 | F30: 8300 | G30: 9300 | H30: =E30*F30 -> 99600 | I30: =E30*G30 -> 111600 | J30: =SUM(H30,I30) -> 211200
A31: 3 | B31: Cọc tiếp địa L=2.4m, D16 | C31: Ấn độ | D31: Cọc | E31: 6 | F31: 218500 | G31: 46500 | H31: =E31*F31 -> 1311000 | I31: =E31*G31 -> 279000 | J31: =SUM(H31,I31) -> 1590000
A32: 4 | B32: Hộp kiểm tra điện trở | C32: VN | D32: Cái | E32: 1 | F32: 491600 | G32: 139500 | H32: =E32*F32 -> 491600 | I32: =E32*G32 -> 139500 | J32: =SUM(H32,I32) -> 631100
A33: 5 | B33: Hàn hóa nhiệt | C33: VN | D33: Mối | E33: 6 | F33: 163800 | G33: 186000 | H33: =E33*F33 -> 982800 | I33: =E33*G33 -> 1116000 | J33: =SUM(H33,I33) -> 2098800
A34: 6 | B34: Hóa chất giảm điện trở | D34: bao | E34: 3 | F34: 305900 | G34: 46500 | H34: =E34*F34 -> 917700 | I34: =E34*G34 -> 139500 | J34: =SUM(H34,I34) -> 1057200
A35: =A34+1 -> 7 | B35: Vật tư phụ | D35: lô | E35: 1 | F35: 546200 | G35: 93000 | H35: =E35*F35 -> 546200 | I35: =E35*G35 -> 93000 | J35: =SUM(H35,I35) -> 639200
A36: IV | B36: HỆ THỐNG TIẾP ĐỊA TỦ ĐIỆN MDB-3A | F36: 0 | G36: 0 | H36: =SUM(H37:H43) -> 8503600 | I36: =SUM(I37:I43) -> 2377200 | J36: =SUM(J37:J43) -> 10880800
A37: 1 | B37: Cáp đồng trần 70mm2 | C37: Cadisun- Việt Nam | D37: Mét | E37: 27 | F37: 154800 | G37: 19500 | H37: =E37*F37 -> 4179600 | I37: =E37*G37 -> 526500 | J37: =SUM(H37,I37) -> 4706100
A38: 2 | B38: Ống xoắn ruột gà HDPE D50/40 | C38: TC- Việt Nam | D38: Mét | E38: 9 | F38: 8300 | G38: 9300 | H38: =E38*F38 -> 74700 | I38: =E38*G38 -> 83700 | J38: =SUM(H38,I38) -> 158400
A39: 3 | B39: Cọc tiếp địa L=2.4m, D16 | C39: Ấn độ | D39: Cọc | E39: 6 | F39: 218500 | G39: 46500 | H39: =E39*F39 -> 1311000 | I39: =E39*G39 -> 279000 | J39: =SUM(H39,I39) -> 1590000
A40: 4 | B40: Hộp kiểm tra điện trở | C40: VN | D40: Cái | E40: 1 | F40: 491600 | G40: 139500 | H40: =E40*F40 -> 491600 | I40: =E40*G40 -> 139500 | J40: =SUM(H40,I40) -> 631100
A41: 5 | B41: Hàn hóa nhiệt | C41: VN | D41: Mối | E41: 6 | F41: 163800 | G41: 186000 | H41: =E41*F41 -> 982800 | I41: =E41*G41 -> 1116000 | J41: =SUM(H41,I41) -> 2098800
...

Sheet 04.HỆ THỐNG CHỐNG SÉT
A1: CHI TIẾT DỰ TOÁN
B2: =BIA!B14 -> CÔNG TRÌNH: TRANG TRẠI CHĂN NUÔI LỢN CÔNG NGHỆ CAO TẠI XÃ QUẢNG SƠN, HUYỆN HẢI HÀ
B3: =BIA!B15 -> ĐỊA ĐIỂM: XÃ QUẢNG SƠN, HUYỆN HẢI HÀ, TỈNH QUẢNG NINH
B4: =BIA!B16 -> CHỦ ĐẦU TƯ: CÔNG TY CỔ PHẦN CHĂN NUÔI GREENTECH
B5: NHÀ THẦU ĐIỆN : CÔNG TY TNHH KỸ THUẬT ĐIỆN VÀ CÔNG NGHỆ MÔI TRƯỜNG DH
B6: HẠNG MỤC P2-04: HỆ THỐNG CHỐNG SÉT
A7: STT | B7: NỘI DUNG CÔNG VIỆC | C7: XUẤT XỨ | D7: ĐVT | E7: Khối Lượng | F7: ĐƠN GIÁ | H7: Thành tiền | J7: Tổng Khối lượng | K7: GHI CHÚ
F8: Vật tư | G8: Nhân công | H8: Vật tư | I8: Nhân công
A9: I | B9: HỆ THỐNG CHỐNG SÉT
A10: 1 | B10: Kim thu sét Rp=97m | C10: Erico/Liva-EU | D10: bộ | E10: 15 | F10: 4916200 | G10: 465000 | H10: =E10*F10 -> 73743000 | I10: =E10*G10 -> 6975000 | J10: =SUM(H10,I10) -> 80718000
A11: 2 | B11: Kim thu sét Rp=61m | C11: Erico/Liva-EU | D11: bộ | E11: 2 | F11: 3325000 | G11: 465000 | H11: =E11*F11 -> 6650000 | I11: =E11*G11 -> 930000 | J11: =SUM(H11,I11) -> 7580000 | K11: Thay đổi
A12: 3 | B12: Trụ bê tông 12m | C12: VN | D12: trụ | E12: 15 | F12: 3823700 | G12: 1395000 | H12: =E12*F12 -> 57355500 | I12: =E12*G12 -> 20925000 | J12: =SUM(H12,I12) -> 78280500
A13: 4 | B13: Cáp đồng trần 70mm2 | C13: Cadisun- Việt Nam | D13: m | E13: 693 | F13: 154800 | G13: 19500 | H13: =E13*F13 -> 107276400 | I13: =E13*G13 -> 13513500 | J13: =SUM(H13,I13) -> 120789900
A14: 5 | B14: Ống uPVC D34 | C14: Bình minh | D14: m | E14: 214 | F14: 22300 | G14: 9700 | H14: =E14*F14 -> 4772200 | I14: =E14*G14 -> 2075800 | J14: =SUM(H14,I14) -> 6848000
A15: 6 | B15: Cọc tiếp địa L=2.4m, D16 | C15: Ấn độ | D15: cọc | E15: 102 | F15: 21800 | G15: 46500 | H15: =E15*F15 -> 2223600 | I15: =E15*G15 -> 4743000 | J15: =SUM(H15,I15) -> 6966600
A16: 7 | B16: Hộp kiểm tra điện trở | C16: VN | D16: bộ | E16: 15 | F16: 491600 | G16: 139500 | H16: =E16*F16 -> 7374000 | I16: =E16*G16 -> 2092500 | J16: =SUM(H16,I16) -> 9466500
A17: 8 | B17: Hàn hóa nhiệt | C17: VN | D17: Mối | E17: 102 | F17: 163800 | G17: 186000 | H17: =E17*F17 -> 16707600 | I17: =E17*G17 -> 18972000 | J17: =SUM(H17,I17) -> 35679600
A18: 9 | B18: Cột thép Inox D60 cao 3m | C18: VN | D18: bộ | E18: 15 | F18: 2731200 | G18: 465000 | H18: =E18*F18 -> 40968000 | I18: =E18*G18 -> 6975000 | J18: =SUM(H18,I18) -> 47943000
A19: 10 | B19: Móng bê tông đỡ trụ KT 800x800x1000mm | C19: VN | D19: móng | E19: 15 | F19: 4370000 | G19: 697500 | H19: =E19*F19 -> 65550000 | I19: =E19*G19 -> 10462500 | J19: =SUM(H19,I19) -> 76012500
A20: 11 | B20: Nghiệm thu và cấp phép | C20: TT giám định Miền Nam | D20: Hệ | E20: 1 | F20: 0 | G20: 5115000 | H20: =E20*F20 -> 0 | I20: =E20*G20 -> 5115000 | J20: =SUM(H20,I20) -> 5115000
A21: 12 | B21: Kẹp liên kết trụ inox với trụ betong | C21: VN | D21: bộ | E21: 30 | F21: 54600 | G21: 18600 | H21: =E21*F21 -> 1638000 | I21: =E21*G21 -> 558000 | J21: =SUM(H21,I21) -> 2196000
A22: 13 | B22: Kẹp liên kết ống luồn dây cáp với trụ betong | C22: VN | D22: bộ | E22: 60 | F22: 54600 | G22: 23200 | H22: =E22*F22 -> 3276000 | I22: =E22*G22 -> 1392000 | J22: =SUM(H22,I22) -> 4668000
A23: 14 | B23: Hóa chất giảm điện trở | D23: bao | E23: 30 | F23: 305900 | G23: 46500 | H23: =E23*F23 -> 9177000 | I23: =E23*G23 -> 1395000 | J23: =SUM(H23,I23) -> 10572000
A24: 15 | B24: Ống xoắn ruột gà HDPE 40/30 | C24: TC- Việt Nam | D24: m | E24: 199 | F24: 8300 | G24: 9300 | H24: =E24*F24 -> 1651700 | I24: =E24*G24 -> 1850700 | J24: =SUM(H24,I24) -> 3502400
A25: 16 | B25: Phụ kiện lắp đặt | D25: hệ | E25: 1 | F25: 4916200 | G25: 1395000 | H25: =E25*F25 -> 4916200 | I25: =E25*G25 -> 1395000 | J25: =SUM(H25,I25) -> 6311200
A26: 17 | B26: Đào và lắp đất | D26: m3 | E26: 102 | F26: 0 | G26: 139500 | H26: =E26*F26 -> 0 | I26: =E26*G26 -> 14229000 | J26: =SUM(H26,I26) -> 14229000
A27: II | B27: CÔNG TÁC KHÁC
A28: 1 | B28: Khuôn hàn | D28: Cái | E28: 5 | F28: 1500000 | G28: 1000000 | H28: =F28*E28 -> 7500000 | I28: =G28*E28 -> 5000000 | J28: =I28+H28 -> 12500000
A29: 2 | B29: Chi phí vận chuyển, xe nâng, giáo lắp đặt | D29: lot | E29: 1 | F29: 0 | G29: 3500000 | H29: =F29*E29 -> 0 | I29: =G29*E29 -> 3500000 | J29: =I29+H29 -> 3500000
A30: 3 | B30: Chi phí T&C | D30: lot | E30: 1 | F30: 0 | G30: 2500000 | H30: =F30*E30 -> 0 | I30: =G30*E30 -> 2500000 | J30: =I30+H30 -> 2500000
A31: TỔNG CỘNG B | H31: =SUM(H28:H30) -> 7500000 | I31: =SUM(I28:I30) -> 11000000 | J31: =SUM(J28:J30) -> 18500000
A32: TỔNG CỘNG A | H32: =+SUM(H10:H26) -> 403279200 | I32: =+SUM(I10:I26) -> 113599000 | J32: =+SUM(J10:J26) -> 516878200
A33: TỔNG CỘNG A+B (trước VAT) | H33: =H32+H31 -> 410779200 | I33: =I32+I31 -> 124599000 | J33: =J32+J31 -> 535378200

Sheet 05.TỦ ĐIỆN
A1: CHI TIẾT DỰ TOÁN
B2: =BIA!B14 -> CÔNG TRÌNH: TRANG TRẠI CHĂN NUÔI LỢN CÔNG NGHỆ CAO TẠI XÃ QUẢNG SƠN, HUYỆN HẢI HÀ
B3: =BIA!B15 -> ĐỊA ĐIỂM: XÃ QUẢNG SƠN, HUYỆN HẢI HÀ, TỈNH QUẢNG NINH
B4: =BIA!B16 -> CHỦ ĐẦU TƯ: CÔNG TY CỔ PHẦN CHĂN NUÔI GREENTECH
B5: NHÀ THẦU ĐIỆN : CÔNG TY TNHH KỸ THUẬT ĐIỆN VÀ CÔNG NGHỆ MÔI TRƯỜNG DH
B6: HẠNG MỤC P2-05: TỦ ĐIỆN (THIẾT BỊ ĐÓNG CẮT LS/Mitsubishi)
A7: STT | B7: NỘI DUNG CÔNG VIỆC | C7: XUẤT XỨ | D7: ĐVT | E7: Khối Lượng | F7: ĐƠN GIÁ | H7: THÀNH TIỀN | J7: Tổng khối lượng | K7: GHI CHÚ
F8: Vật tư | G8: Nhân công | H8: Vật tư | I8: Nhân công
A9: A | B9: TỦ ĐIỆN PHÂN PHỐI CHÍNH | H9: =SUM(H10:H24) -> 1593758000 | I9: =SUM(I10:I24) -> 27100000 | J9: =SUM(J10:J24) -> 1620858000
A10: I | B10: TỦ ĐIỆN MSB-A | C10: DH- Việt Nam | D10: Bộ | E10: 1 | F10: 218000000 | G10: 3500000 | H10: =E10*F10 -> 218000000 | I10: =E10*G10 -> 3500000 | J10: =SUM(H10,I10) -> 221500000
A11: I.1 | B11: TỦ ĐIỆN MSB-A.1-ATS SECTION | C11: DH- Việt Nam | D11: Bộ | E11: 1 | F11: 178500000 | G11: 1500000 | H11: =E11*F11 -> 178500000 | I11: =E11*G11 -> 1500000 | J11: =SUM(H11,I11) -> 180000000
A12: I.2 | B12: TỦ ĐIỆN MSB-A.2-ATS SECTION | C12: DH- Việt Nam | D12: Bộ | E12: 1 | F12: 178500000 | G12: 1500000 | H12: =E12*F12 -> 178500000 | I12: =E12*G12 -> 1500000 | J12: =SUM(H12,I12) -> 180000000
A13: II | B13: TỦ ĐIỆN MSB-B | C13: DH- Việt Nam | D13: Bộ | E13: 1 | F13: 351900000 | G13: 3500000 | H13: =E13*F13 -> 351900000 | I13: =E13*G13 -> 3500000 | J13: =SUM(H13,I13) -> 355400000
A14: II.1 | B14: TỦ ĐIỆN MSB-B.1-ATS SECTION | C14: DH- Việt Nam | D14: Bộ | E14: 1 | F14: 214000000 | G14: 1500000 | H14: =E14*F14 -> 214000000 | I14: =E14*G14 -> 1500000 | J14: =SUM(H14,I14) -> 215500000
A15: II.2 | B15: TỦ ĐIỆN MSB-B.2-ATS SECTION | C15: DH- Việt Nam | D15: Bộ | E15: 1 | F15: 210000000 | G15: 1500000 | H15: =E15*F15 -> 210000000 | I15: =E15*G15 -> 1500000 | J15: =SUM(H15,I15) -> 211500000
A16: III | B16: TỦ ĐIỆN MDB-1A | C16: DH- Việt Nam | D16: Bộ | E16: 1 | F16: 24485000 | G16: 1200000 | H16: =E16*F16 -> 24485000 | I16: =E16*G16 -> 1200000 | J16: =SUM(H16,I16) -> 25685000
A17: IV | B17: TỦ ĐIỆN MDB-2A | C17: DH- Việt Nam | D17: Bộ | E17: 1 | F17: 21663000 | G17: 1200000 | H17: =E17*F17 -> 21663000 | I17: =E17*G17 -> 1200000 | J17: =SUM(H17,I17) -> 22863000
A18: V | B18: TỦ ĐIỆN MDB-3A | C18: DH- Việt Nam | D18: Bộ | E18: 1 | F18: 16268000 | G18: 1000000 | H18: =E18*F18 -> 16268000 | I18: =E18*G18 -> 1000000 | J18: =SUM(H18,I18) -> 17268000
A19: VI | B19: TỦ ĐIỆN MDB-1B | C19: DH- Việt Nam | D19: Bộ | E19: 1 | F19: 23323000 | G19: 1200000 | H19: =E19*F19 -> 23323000 | I19: =E19*G19 -> 1200000 | J19: =SUM(H19,I19) -> 24523000
A20: VII | B20: TỦ ĐIỆN MDB-2B | C20: DH- Việt Nam | D20: Bộ | E20: 1 | F20: 32785000 | G20: 1500000 | H20: =E20*F20 -> 32785000 | I20: =E20*G20 -> 1500000 | J20: =SUM(H20,I20) -> 34285000
A21: VIII | B21: TỦ ĐIỆN MDB-3B ( 3B.1 & 3B.2) | C21: DH- Việt Nam | D21: Bộ | E21: 2 | F21: 13695000 | G21: 1000000 | H21: =E21*F21 -> 27390000 | I21: =E21*G21 -> 2000000 | J21: =SUM(H21,I21) -> 29390000
... A24: XI | B24: TỦ ĐIỆN MDB-6B | C24: DH- Việt Nam | D24: Bộ | E24: 1 | F24: 23240000 | G24: 1200000 | H24: =E24*F24 -> 23240000 | I24: =E24*G24 -> 1200000 | J24: =SUM(H24,I24) -> 24440000
A25: B | B25: TỦ ĐIỆN HẠNG MỤC CHÍNH | C25: DH- Việt Nam | F25: 0 | H25: =SUM(H26:H39) -> 823061200 | I25: =SUM(I26:I39) -> 83850000 | J25: =SUM(J26:J39) -> 906911200
A26: I | B26: TỦ ĐIỆN DB-1 | C26: DH- Việt Nam | D26: Bộ | E26: 1 | F26: 9545000 | G26: 1000000 | H26: =E26*F26 -> 9545000 | I26: =E26*G26 -> 1000000 | J26: =SUM(H26,I26) -> 10545000
A27: II | B27: TỦ ĐIỆN DB-2 | C27: DH- Việt Nam | D27: Bộ | E27: 1 | F27: 9711000 | G27: 1000000 | H27: =E27*F27 -> 9711000 | I27: =E27*G27 -> 1000000 | J27: =SUM(H27,I27) -> 10711000
A28: III | B28: TỦ ĐIỆN DB-3 | C28: DH- Việt Nam | D28: Bộ | E28: 1 | F28: 10043000 | G28: 1000000 | H28: =E28*F28 -> 10043000 | I28: =E28*G28 -> 1000000 | J28: =SUM(H28,I28) -> 11043000
A29: IV | B29: TỦ ĐIỆN DB-3.1 | C29: DH- Việt Nam | D29: Bộ | E29: 1 | F29: 4233000 | G29: 750000 | H29: =E29*F29 -> 4233000 | I29: =E29*G29 -> 750000 | J29: =SUM(H29,I29) -> 4983000
A30: V | B30: TỦ ĐIỆN DB-4.1 | C30: DH- Việt Nam | D30: Bộ | E30: 1 | F30: 17504700 | G30: 1200000 | H30: =E30*F30 -> 17504700 | I30: =E30*G30 -> 1200000 | J30: =SUM(H30,I30) -> 18704700
A31: VI | B31: TỦ ĐIỆN DB-4.2 | C31: DH- Việt Nam | D31: Bộ | E31: 1 | F31: 16019000 | G31: 1000000 | H31: =E31*F31 -> 16019000 | I31: =E31*G31 -> 1000000 | J31: =SUM(H31,I31) -> 17019000
A32: VII | B32: TỦ ĐIỆN DB-5.1 | C32: DH- Việt Nam | D32: Bộ | E32: 1 | F32: 28635000 | G32: 1500000 | H32: =E32*F32 -> 28635000 | I32: =E32*G32 -> 1500000 | J32: =SUM(H32,I32) -> 30135000
A33: VIII | B33: TỦ ĐIỆN DB-5.2 | C33: DH- Việt Nam | D33: Bộ | E33: 0 | F33: 28635000 | G33: 1500000 | H33: =E33*F33 -> 0 | I33: =E33*G33 -> 0 | J33: =SUM(H33,I33) -> 0 | K33: ko có
A34: IX | B34: Tủ điện MCC-5.1.1~10, MCC-5.2.1~10. | C34: DH- Việt Nam | D34: Bộ | E34: =10+10 -> 20 | F34: 10001500 | G34: 1000000 | H34: =E34*F34 -> 200030000 | I34: =E34*G34 -> 20000000 | J34: =SUM(H34,I34) -> 220030000
A35: X | B35: TỦ ĐIỆN DB-6.1 | C35: DH- Việt Nam | D35: Bộ | E35: 1 | F35: 21331000 | G35: 1200000 | H35: =E35*F35 -> 21331000 | I35: =E35*G35 -> 1200000 | J35: =SUM(H35,I35) -> 22531000
A36: XI | B36: TỦ ĐIỆN DB-6.2 | C36: DH- Việt Nam | D36: Bộ | E36: 1 | F36: 21621500 | G36: 1200000 | H36: =E36*F36 -> 21621500 | I36: =E36*G36 -> 1200000 | J36: =SUM(H36,I36) -> 22821500
A37: XII | B37: TỦ ĐIỆN DB-6.1.1~7, DB-6.2.1~7. | C37: DH- Việt Nam | D37: Bộ | E37: 14 | F37: 10126000 | G37: 1000000 | H37: =E37*F37 -> 141764000 | I37: =E37*G37 -> 14000000 | J37: =SUM(H37,I37) -> 155764000
A38: XIII | B38: TỦ ĐIỆN DB-7.1~16. | C38: DH- Việt Nam | D38: Bộ | E38: 16 | F38: 9213000 | G38: 1000000 | H38: =E38*F38 -> 147408000 | I38: =E38*G38 -> 16000000 | J38: =SUM(H38,I38) -> 163408000
A39: XIV | B39: TỦ ĐIỆN DB-7.1~16.1 ; DB-7.1~16.2. | C39: DH- Việt Nam | D39: Bộ | E39: 32 | F39: 6100500 | G39: 750000 | H39: =E39*F39 -> 195216000 | I39: =E39*G39 -> 24000000 | J39: =SUM(H39,I39) -> 219216000
A40: C | B40: TỦ ĐIỆN CÁC MỤC PHỤ | C40: DH- Việt Nam | F40: 0 | H40: =SUM(H41:H62) -> 107244300 | I40: =SUM(I41:I62) -> 18150000 | J40: =SUM(J41:J62) -> 125394300
A41: II | B41: TỦ ĐIỆN DB-9 | C41: DH- Việt Nam | D41: Bộ | E41: 1 | F41: 4399000 | G41: 750000 | H41: =E41*F41 -> 4399000 | I41: =E41*G41 -> 750000 | J41: =SUM(H41,I41) -> 5149000
A42: III | B42: Tủ điện DB-10 | C42: DH- Việt Nam | D42: Bộ | E42: 1 | F42: 2448500 | G42: 750000 | H42: =E42*F42 -> 2448500 | I42: =E42*G42 -> 750000 | J42: =SUM(H42,I42) -> 3198500
...

Sheet 06.HỆ THỐNG CHIẾU SÁNG BÊN TRON
A1: CHI TIẾT DỰ TOÁN
B2: =BIA!B14 -> CÔNG TRÌNH: TRANG TRẠI CHĂN NUÔI LỢN CÔNG NGHỆ CAO TẠI XÃ QUẢNG SƠN, HUYỆN HẢI HÀ
B3: =BIA!B15 -> ĐỊA ĐIỂM: XÃ QUẢNG SƠN, HUYỆN HẢI HÀ, TỈNH QUẢNG NINH
B4: =BIA!B16 -> CHỦ ĐẦU TƯ: CÔNG TY CỔ PHẦN CHĂN NUÔI GREENTECH
B5: NHÀ THẦU ĐIỆN : CÔNG TY TNHH KỸ THUẬT ĐIỆN VÀ CÔNG NGHỆ MÔI TRƯỜNG DH
B6: HẠNG MỤC P2-06: HỆ THÔNG CHIẾU SÁNG BÊN TRONG
A7: STT | B7: NỘI DUNG CÔNG VIỆC | C7: XUẤT XỨ | D7: ĐVT | E7: Khối Lượng | F7: ĐƠN GIÁ | H7: Thành tiền | J7: Tổng Khối lượng | K7: GHI CHÚ
F8: Vật tư | G8: Nhân công | H8: Vật tư | I8: Nhân công
A9: I | B9: CHUỒNG HEO CAI SỮA | D9: 2 | H9: =SUM(H10:H39)*D9 -> 608048600 | I9: =SUM(I10:I39)*D9 -> 216536200 | J9: =SUM(J10:J39)*D9 -> 824584800
A10: 1 | B10: Đèn led buld 40W | C10: Duhal- Việt Nam | D10: bộ | E10: 110 | F10: 126700 | G10: 34400 | H10: =E10*F10 -> 13937000 | I10: =E10*G10 -> 3784000 | J10: =SUM(H10,I10) -> 17721000
A11: 2 | B11: Đèn led buld 20W | C11: Duhal- Việt Nam | D11: bộ | E11: 19 | F11: 60200 | G11: 32500 | H11: =E11*F11 -> 1143800 | I11: =E11*G11 -> 617500 | J11: =SUM(H11,I11) -> 1761300 | K11: Thay đổi
A12: 3 | B12: Công tắc ba 1 chiều 16A | C12: Sino- Việt Nam | D12: bộ | E12: 7 | F12: 56100 | G12: 23200 | H12: =E12*F12 -> 392700 | I12: =E12*G12 -> 162400 | J12: =SUM(H12,I12) -> 555100
A13: 4 | B13: Công tắc đôi 1 chiều 16A | C13: Sino- Việt Nam | D13: bộ | E13: 2 | F13: 42000 | G13: 18600 | H13: =E13*F13 -> 84000 | I13: =E13*G13 -> 37200 | J13: =SUM(H13,I13) -> 121200
A14: 5 | B14: Công tắc đơn 2 chiều 16A | C14: Sino- Việt Nam | D14: bộ | E14: 2 | F14: 42100 | G14: 23200 | H14: =E14*F14 -> 84200 | I14: =E14*G14 -> 46400 | J14: =SUM(H14,I14) -> 130600
A15: 6 | B15: Ổ cắm đôi 3 chấu 16A | C15: Sino- Việt Nam | D15: bộ | E15: 336 | F15: 70100 | G15: 32500 | H15: =E15*F15 -> 23553600 | I15: =E15*G15 -> 10920000 | J15: =SUM(H15,I15) -> 34473600
A16: 7 | B16: Ổ cắm công nghiệp 3 pha chống nước | C16: Sino- Việt Nam | D16: bộ | E16: 7 | F16: 268500 | G16: 46500 | H16: =E16*F16 -> 1879500 | I16: =E16*G16 -> 325500 | J16: =SUM(H16,I16) -> 2205000
A17: 8 | B17: Cáp Cu/PVC 2x1C-1.5mm² từ đèn đến công tắc | C17: Cadisun- Việt Nam | D17: m | E17: 1773 | F17: 7200 | G17: 2700 | H17: =E17*F17 -> 12765600 | I17: =E17*G17 -> 4787100 | J17: =SUM(H17,I17) -> 17552700
A18: 9 | B18: Cáp Cu/PVC 1C-1.5mm² (E) từ đèn đến công tắc | C18: Cadisun- Việt Nam | D18: m | F18: 3600 | G18: 1300 | H18: =E18*F18 -> 0 | I18: =E18*G18 -> 0 | J18: =SUM(H18,I18) -> 0 | K18: Bỏ dây PE
A19: 10 | B19: Cáp Cu/PVC 2x1C-2.5mm² từ công tắc đến MCB | C19: Cadisun- Việt Nam | D19: m | E19: 84 | F19: 12100 | G19: 3700 | H19: =E19*F19 -> 1016400 | I19: =E19*G19 -> 310800 | J19: =SUM(H19,I19) -> 1327200
A20: 11 | B20: Cáp Cu/PVC 1x1C-2.5mm² ( E) từ công tắc đến MCB | C20: Cadisun- Việt Nam | D20: m | E20: 84 | F20: 6000 | G20: 1800 | H20: =E20*F20 -> 504000 | I20: =E20*G20 -> 151200 | J20: =SUM(H20,I20) -> 655200
A21: 12 | B21: Cáp Cu/PVC 2x1C -4mm² ổ cắm điện 1 pha | C21: Cadisun- Việt Nam | D21: m | E21: 2284 | F21: 19000 | G21: 6500 | H21: =E21*F21 -> 43396000 | I21: =E21*G21 -> 14846000 | J21: =SUM(H21,I21) -> 58242000
A22: 13 | B22: Cáp Cu/PVC 1x1C -2.5mm² (E)ổ cắm điện 1 pha | C22: Cadisun- Việt Nam | D22: m | E22: 2284 | F22: 6000 | G22: 1800 | H22: =E22*F22 -> 13704000 | I22: =E22*G22 -> 4111200 | J22: =SUM(H22,I22) -> 17815200
A23: 14 | B23: Cáp Cu/PVC 2x1C -6mm² ổ cắm điện 1 pha | C23: Cadisun- Việt Nam | D23: m | E23: 0 | F23: 29100 | G23: 10200 | H23: =E23*F23 -> 0 | I23: =E23*G23 -> 0 | J23: =SUM(H23,I23) -> 0
A24: 15 | B24: Cáp Cu/PVC 1x1C -6mm² (E) ổ cắm điện 1 pha | C24: Cadisun- Việt Nam | D24: m | E24: 0 | F24: 14500 | G24: 5100 | H24: =E24*F24 -> 0 | I24: =E24*G24 -> 0 | J24: =SUM(H24,I24) -> 0
A25: 16 | B25: Ống điện PVC D20 | C25: Sino- Việt Nam | D25: m | E25: 2214 | F25: 6600 | G25: 9300 | H25: =E25*F25 -> 14612400 | I25: =E25*G25 -> 20590200 | J25: =SUM(H25,I25) -> 35202600
A26: 17 | B26: Ống điện PVC D25 | C26: Sino- Việt Nam | D26: m | E26: 218 | F26: 9300 | G26: 13900 | H26: =E26*F26 -> 2027400 | I26: =E26*G26 -> 3030200 | J26: =SUM(H26,I26) -> 5057600
A27: 18 | B27: Cáp Cu/PVC 4x1C -4mm² ổ cắm điện 3 pha | C27: Cadisun- Việt Nam | D27: m | E27: 71 | F27: 38100 | G27: 13000 | H27: =E27*F27 -> 2705100 | I27: =E27*G27 -> 923000 | J27: =SUM(H27,I27) -> 3628100
A28: 19 | B28: Cáp Cu/PVC 1C-2.5mm2 dây E cho ổ cắm điện 3 pha | C28: Cadisun- Việt Nam | D28: m | E28: 71 | F28: 6000 | G28: 1800 | H28: =E28*F28 -> 426000 | I28: =E28*G28 -> 127800 | J28: =SUM(H28,I28) -> 553800
A29: 20 | B29: Cáp Cu/XLPE/PVC 4x1C-16mm² Dây cấp nguồn từ tủ DB-01B.1-->DB-01B.7 | C29: Cadisun- Việt Nam | D29: m | E29: 358 | F29: 153300 | G29: 37200 | H29: =E29*F29 -> 54881400 | I29: =E29*G29 -> 13317600 | J29: =SUM(H29,I29) -> 68199000
A30: 21 | B30: Cáp Cu/PVC 1C-16mm² (E) cấp nguồn từ tủ DB-01B.1-->DB-01B.7 | C30: Cadisun- Việt Nam | D30: m | E30: 358 | F30: 36500 | G30: 9300 | H30: =E30*F30 -> 13067000 | I30: =E30*G30 -> 3329400 | J30: =SUM(H30,I30) -> 16396400
... A35: 26 | B35: Cáp Cu/PVC 1C-10mm² (E) cấp nguồn cho hệ thống tự động | C35: Cadisun- Việt Nam | D35: m | E35: 72 | F35: 24300 | G35: 5500 | H35: =E35*F35 -> 1749600 | I35: =E35*G35 -> 396000 | J35: =SUM(H35,I35) -> 2145600
A36: 27 | B36: Khay cáp + nắp + nối 150x50 mm Tol 1.0 mm | C36: DHME- Việt Nam | D36: m | E36: 0 | F36: 157200 | G36: 41800 | H36: =E36*F36 -> 0 | I36: =E36*G36 -> 0 | J36: =SUM(H36,I36) -> 0 | K36: Thay đổi độ dày
A37: 28 | B37: Khay cáp + nắp + nối 150x50 mm Tol 1.0 mm | C37: DHME- Việt Nam | D37: m | E37: 285 | F37: 157200 | G37: 41800 | H37: =E37*F37 -> 44802000 | I37: =E37*G37 -> 11913000 | J37: =SUM(H37,I37) -> 56715000 | K37: Thay đổi độ dày
A38: 29 | B38: Khay cáp + nắp + nối 75x50 mm Tol 1.0 mm | C38: DHME- Việt Nam | D38: m | E38: 246 | F38: 110400 | G38: 27900 | H38: =E38*F38 -> 27158400 | I38: =E38*G38 -> 6863400 | J38: =SUM(H38,I38) -> 34021800 | K38: Thay đổi độ dày
A39: 30 | B39: Vật tư phụ và phụ kiện đấu nối | C39: VN | D39: lô | E39: 1 | F39: 18715000 | G39: 5115000 | H39: =E39*F39 -> 18715000 | I39: =E39*G39 -> 5115000 | J39: =SUM(H39,I39) -> 23830000
A40: II | B40: CHUỒNG HEO THỊT | D40: 16 | F40: 0 | G40: 0 | H40: =SUM(H41:H63)*D40 -> 2245326400 | I40: =SUM(I41:I63)*D40 -> 777574400 | J40: =SUM(J41:J63)*D40 -> 3022900800
A41: 1 | B41: Cáp CXV 4x1C-50mm2 từ các tủ MDB 3b, MDB 4B, MDB 5 B, MDB 6B đến các tủ DB1A.1 …….DB1A.16 | C41: Cadisun- Việt Nam | D41: m | E41: 43 | F41: 436000 | G41: 74400 | H41: =E41*F41 -> 18748000 | I41: =E41*G41 -> 3199200 | J41: =SUM(H41,I41) -> 21947200
A42: 2 | B42: Cáp CXV 1x1C-25mm2 từ các tủ MDB 3b, MDB 4B, MDB 5 B, MDB 6B đến các tủ DB1A.1 …….DB1A.16 | C42: Cadisun- Việt Nam | D42: m | E42: 43 | F42: 58000 | G42: 11600 | H42: =E42*F42 -> 2494000 | I42: =E42*G42 -> 498800 | J42: =SUM(H42,I42) -> 2992800
A43: 3 | B43: Cáp CXV 4x1C-16mm2 từ các tủ DB1A.1 đến các tủ DB1A.1 .1…….DB1A.1.2 | C43: Cadisun- Việt Nam | D43: m | E43: 37 | F43: 153300 | G43: 37200 | H43: =E43*F43 -> 5672100 | I43: =E43*G43 -> 1376400 | J43: =SUM(H43,I43) -> 7048500
A44: 4 | B44: Cáp Cu/PVC/PVC 1x4Cx1.5mm2 cho mô tơ cào phân | C44: Cadisun- Việt Nam | D44: m | E44: 358 | F44: 16800 | G44: 5500 | H44: =E44*F44 -> 6014400 | I44: =E44*G44 -> 1969000 | J44: =SUM(H44,I44) -> 7983400
...

Sheet 05. TỦ ĐIỆN CHI TIẾT
A1: STT | B1: Mô tả thiết bị | C1: Mã sản phẩm | D1: Hãng sản xuất | E1: ĐVT | F1: Số Lượng | G1: Ghi chú
A2: I | B2: Hệ thống tủ hạ thể tổng
A3: 1 | B3: Tủ điện MSB-A | D3: Việt Nam | E3: Tủ | F3: 1
B4: Vỏ tủ : Kiểu trong nhà, đặt sàn, sơn tĩnh điện, Form 1B Kích thước : 2200Hx2000Wx1000Dx2mm, 2 lớp cánh | D4: DH- Việt Nam | E4: Cái | F4: 1
B5: Đầu vào | E5: Cái | F5: 1
B6: ACB 4P 1250A 65kA | C6: AE1250-SW 4P 1250A FIX | D6: Mitsubishi-JP/CN | E6: Cái | F6: 1 | G6: SĐ1S 50kA
B7: Động cơ ACB 200-250VAC-DC | C7: MD-AD250-W | D7: Mitsubishi-JP/CN | E7: Cái | F7: 1
B8: Cuộn cắt 100-250VAC-DC | C8: SHT-AD250-W | D8: Mitsubishi-JP/CN | E8: Cái | F8: 1
B9: Cuộn đóng | C9: CC-AD250-W | D9: Mitsubishi-JP/CN | E9: Cái | F9: 1
B10: Tiếp điểm phụ | C10: AX-4-W | D10: Mitsubishi-JP/CN | E10: Cái | F10: 1
B11: Chuyển mạch on/off ACB | C11: HY-CSL-1-10A | D11: Hanyoung-Korea | E11: Cái | F11: 1
B12: Đèn báo trạng thái ACB | D12: Idec-JP/CN | E12: Cái | F12: 3
B13: Biến dòng MCT 1200/5A | C13: =INDEX([63]Sheet1!$A$3:$N$69,MATCH(B13,[63]Sheet1!$A$3:$A$69,0),IF("Andeli"=D13,2,IF("Taiwan"=D13,5,IF("Emic"=D13,8)))) -> #N/A | D13: Taiwan | E13: Cái | F13: 4
B14: Biến dòng PCT 1200/5A | C14: =INDEX([64]Sheet1!$A$3:$N$69,MATCH(B14,[64]Sheet1!$A$3:$A$69,0),IF("Andeli"=D14,2,IF("Taiwan"=D14,5,IF("Emic"=D14,8)))) -> PR-6 1200/5A | D14: Taiwan | E14: Cái | F14: 4
B15: Chống sét lan truyền Type1, 3P+N/PE, Imax=120kA, 10/350µs | C15: HDY31206 | D15: Himel | E15: Cái | F15: 1
B16: Cầu chì 220V/125A | D16: Asia | E16: Cái | F16: 4
B17: Cầu chì 220V/2A | D17: Asia | E17: Cái | F17: 3
B18: Đèn tín hiệu báo pha 220V | D18: Idec-JP/CN | E18: Cái | F18: 3
B19: Đòng hồ KTS đo đa chức năng | C19: EM-07K | D19: Tense | E19: Cái | F19: 1
B20: Rơ le bảo vệ quá dòng | C20: NX204A-240A | D20: Mikro-Malaysia | E20: Cái | F20: 1
B21: Rơ le bảo vệ thấp áp và cao áp | C21: MX200A-380A | D21: Mikro-Malaysia | E21: Cái | F21: 1
B22: Rơ le bảo vệ chạm đất | C22: NX201A-240A | D22: Mikro-Malaysia | E22: Cái | F22: 1
B23: Đầu ra
B24: MCCB 3P 400A 42kA | C24: =INDEX([65]MCCB!$B$3:$F$614,MATCH(B24,[65]MCCB!$B$3:$B$614,0),2) -> ABN403c | D24: LS-Korea/CN | E24: Cái | F24: 2 | G24: Bổ sung
B25: MCCB 3P 250A 42kA | C25: =INDEX([65]MCCB!$B$3:$F$614,MATCH(B25,[65]MCCB!$B$3:$B$614,0),2) -> ABS203c | D25: LS-Korea/CN | E25: Cái | F25: 2 | G25: Bổ sung
B26: Khoang tụ bù
B27: MCCB 3P 630A 45kA | C27: =INDEX([65]MCCB!$B$3:$F$614,MATCH(B27,[65]MCCB!$B$3:$B$614,0),2) -> ABN803c | D27: LS-Korea/CN | E27: Cái | F27: 1
B28: MCCB 3P 50A 18kA | C28: =INDEX([65]MCCB!$B$3:$F$614,MATCH(B28,[65]MCCB!$B$3:$B$614,0),2) -> ABN53c | D28: LS-Korea/CN | E28: Cái | F28: 10
B29: Contactor 3P 50A | C29: =INDEX([65]MCCB!$B$3:$F$614,MATCH(B29,[65]MCCB!$B$3:$B$614,0),2) -> MC-50a | D29: LS-Korea/CN | E29: Cái | F29: 10
B30: Tụ bù 25kVAr | C30: =INDEX([66]Sheet1!$A$96:$M$137,MATCH(B30,[66]Sheet1!$A$96:$A$137,0),IF("BTB"=D30,2,IF("Nuintek"=D30,5,IF("Epcos"=D30,8,)))) -> KNE-4134116S | D30: Nuintek | E30: Cái | F30: 10
B31: Cuộn kháng cho tụ bù 25kVAr, 7% | C31: =INDEX([66]Sheet1!$A$96:$M$137,MATCH(B31,[66]Sheet1!$A$96:$A$137,0),IF("BTB"=D31,2,IF("Nuintek"=D31,5,IF("Epcos"=D31,8,)))) -> BRH3-7/400/25 | D31: BTB | E31: Cái | F31: 10
B32: Bộ điều khiển tụ bù 12 cấp | C32: =INDEX([67]Sheet1!$A$2:$D$17,MATCH(B32,[67]Sheet1!$A$2:$A$17,0),2,1) -> #N/A | D32: Mikro-Malaysia | E32: Cái | F32: 1
B33: Cáp đi dây cho tụ bù | D33: VN | E33: Lô | F33: 1
B34: Vật tư nhân công hoàn thiện | E34: Cái | F34: 1
B35: Thanh cái đồng 3P+50%N+25%E | D35: Malaysia/tđ | E35: Cái | F35: 1
B36: Vật tư phụ (Co nhiệt, Ecu, Bulong, dây thít, dây điều khiển, đầu cốt,…) | D36: Asia | E36: Cái | F36: 1
B37: Nhân công lắp ráp tủ | D37: DH- Việt Nam | E37: Tủ | F37: 1
A38: 2 | B38: Tủ điện MSB-A.1-ATS SECTION | D38: Việt Nam | E38: Tủ | F38: 1
B39: Vỏ tủ : Kiểu trong nhà, đặt sàn, sơn tĩnh điện, Form 1B Kích thước : 2200Hx1600Wx1000Dx2mm, 2 lớp cánh | D39: DH- Việt Nam | E39: Cái | F39: 1
B40: 1.Khoang ATS SECTION | E40: Cái | F40: 1
...

Sheet PTH
